<?xml version="1.0" encoding="UTF-8"?>
<testng-results total="4" passed="1" failed="3" skipped="0">
  <reporter-output>
  </reporter-output>
  <suite started-at="2022-12-17T17:58:44Z" name="Default suite" finished-at="2022-12-17T17:59:07Z" duration-ms="23577">
    <groups>
    </groups>
    <test started-at="2022-12-17T17:58:44Z" name="Default test" finished-at="2022-12-17T17:59:07Z" duration-ms="23577">
      <class name="qafactory.swaglabs.testCases.TC002_DataDriven_Login">
        <test-method is-config="true" signature="setup()[pri:0, instance:qafactory.swaglabs.testCases.TC002_DataDriven_Login@1329eff]" started-at="2022-12-17T23:28:44Z" name="setup" finished-at="2022-12-17T23:28:56Z" duration-ms="12371" status="PASS">
          <reporter-output>
          </reporter-output>
        </test-method> <!-- setup -->
        <test-method signature="loginDDT(java.lang.String, java.lang.String)[pri:0, instance:qafactory.swaglabs.testCases.TC002_DataDriven_Login@1329eff]" started-at="2022-12-17T23:29:02Z" name="loginDDT" data-provider="LoginData" finished-at="2022-12-17T23:29:04Z" duration-ms="2695" status="PASS">
          <params>
            <param index="0">
              <value>
                <![CDATA[standard_user]]>
              </value>
            </param>
            <param index="1">
              <value>
                <![CDATA[secret_sauce]]>
              </value>
            </param>
          </params>
          <reporter-output>
          </reporter-output>
        </test-method> <!-- loginDDT -->
        <test-method signature="loginDDT(java.lang.String, java.lang.String)[pri:0, instance:qafactory.swaglabs.testCases.TC002_DataDriven_Login@1329eff]" started-at="2022-12-17T23:29:04Z" name="loginDDT" data-provider="LoginData" finished-at="2022-12-17T23:29:05Z" duration-ms="281" status="FAIL">
          <params>
            <param index="0">
              <value>
                <![CDATA[locked_out_user]]>
              </value>
            </param>
            <param index="1">
              <value>
                <![CDATA[Test1]]>
              </value>
            </param>
          </params>
          <exception class="java.lang.AssertionError">
            <message>
              <![CDATA[expected [https://www.saucedemo.com/] but found [https://www.saucedemo.com/inventory.html]]]>
            </message>
            <full-stacktrace>
              <![CDATA[java.lang.AssertionError: expected [https://www.saucedemo.com/] but found [https://www.saucedemo.com/inventory.html]
	at org.testng.Assert.fail(Assert.java:94)
	at org.testng.Assert.failNotEquals(Assert.java:513)
	at org.testng.Assert.assertEqualsImpl(Assert.java:135)
	at org.testng.Assert.assertEquals(Assert.java:116)
	at org.testng.Assert.assertEquals(Assert.java:190)
	at org.testng.Assert.assertEquals(Assert.java:200)
	at qafactory.swaglabs.testCases.TC002_DataDriven_Login.loginDDT(TC002_DataDriven_Login.java:26)
	at java.base/jdk.internal.reflect.NativeMethodAccessorImpl.invoke0(Native Method)
	at java.base/jdk.internal.reflect.NativeMethodAccessorImpl.invoke(NativeMethodAccessorImpl.java:62)
	at java.base/jdk.internal.reflect.DelegatingMethodAccessorImpl.invoke(DelegatingMethodAccessorImpl.java:43)
	at java.base/java.lang.reflect.Method.invoke(Method.java:566)
	at org.testng.internal.MethodInvocationHelper.invokeMethod(MethodInvocationHelper.java:86)
	at org.testng.internal.Invoker.invokeMethod(Invoker.java:643)
	at org.testng.internal.Invoker.invokeTestMethod(Invoker.java:820)
	at org.testng.internal.Invoker.invokeTestMethods(Invoker.java:1128)
	at org.testng.internal.TestMethodWorker.invokeTestMethods(TestMethodWorker.java:129)
	at org.testng.internal.TestMethodWorker.run(TestMethodWorker.java:112)
	at org.testng.TestRunner.privateRun(TestRunner.java:782)
	at org.testng.TestRunner.run(TestRunner.java:632)
	at org.testng.SuiteRunner.runTest(SuiteRunner.java:366)
	at org.testng.SuiteRunner.runSequentially(SuiteRunner.java:361)
	at org.testng.SuiteRunner.privateRun(SuiteRunner.java:319)
	at org.testng.SuiteRunner.run(SuiteRunner.java:268)
	at org.testng.SuiteRunnerWorker.runSuite(SuiteRunnerWorker.java:52)
	at org.testng.SuiteRunnerWorker.run(SuiteRunnerWorker.java:86)
	at org.testng.TestNG.runSuitesSequentially(TestNG.java:1244)
	at org.testng.TestNG.runSuitesLocally(TestNG.java:1169)
	at org.testng.TestNG.run(TestNG.java:1064)
	at org.testng.remote.AbstractRemoteTestNG.run(AbstractRemoteTestNG.java:126)
	at org.testng.remote.RemoteTestNG.initAndRun(RemoteTestNG.java:152)
	at org.testng.remote.RemoteTestNG.main(RemoteTestNG.java:57)
]]>
            </full-stacktrace>
          </exception> <!-- java.lang.AssertionError -->
          <reporter-output>
          </reporter-output>
        </test-method> <!-- loginDDT -->
        <test-method signature="loginDDT(java.lang.String, java.lang.String)[pri:0, instance:qafactory.swaglabs.testCases.TC002_DataDriven_Login@1329eff]" started-at="2022-12-17T23:29:05Z" name="loginDDT" data-provider="LoginData" finished-at="2022-12-17T23:29:05Z" duration-ms="371" status="FAIL">
          <params>
            <param index="0">
              <value>
                <![CDATA[problem_user]]>
              </value>
            </param>
            <param index="1">
              <value>
                <![CDATA[Test2]]>
              </value>
            </param>
          </params>
          <exception class="java.lang.AssertionError">
            <message>
              <![CDATA[expected [https://www.saucedemo.com/] but found [https://www.saucedemo.com/inventory.html]]]>
            </message>
            <full-stacktrace>
              <![CDATA[java.lang.AssertionError: expected [https://www.saucedemo.com/] but found [https://www.saucedemo.com/inventory.html]
	at org.testng.Assert.fail(Assert.java:94)
	at org.testng.Assert.failNotEquals(Assert.java:513)
	at org.testng.Assert.assertEqualsImpl(Assert.java:135)
	at org.testng.Assert.assertEquals(Assert.java:116)
	at org.testng.Assert.assertEquals(Assert.java:190)
	at org.testng.Assert.assertEquals(Assert.java:200)
	at qafactory.swaglabs.testCases.TC002_DataDriven_Login.loginDDT(TC002_DataDriven_Login.java:26)
	at java.base/jdk.internal.reflect.NativeMethodAccessorImpl.invoke0(Native Method)
	at java.base/jdk.internal.reflect.NativeMethodAccessorImpl.invoke(NativeMethodAccessorImpl.java:62)
	at java.base/jdk.internal.reflect.DelegatingMethodAccessorImpl.invoke(DelegatingMethodAccessorImpl.java:43)
	at java.base/java.lang.reflect.Method.invoke(Method.java:566)
	at org.testng.internal.MethodInvocationHelper.invokeMethod(MethodInvocationHelper.java:86)
	at org.testng.internal.Invoker.invokeMethod(Invoker.java:643)
	at org.testng.internal.Invoker.invokeTestMethod(Invoker.java:820)
	at org.testng.internal.Invoker.invokeTestMethods(Invoker.java:1128)
	at org.testng.internal.TestMethodWorker.invokeTestMethods(TestMethodWorker.java:129)
	at org.testng.internal.TestMethodWorker.run(TestMethodWorker.java:112)
	at org.testng.TestRunner.privateRun(TestRunner.java:782)
	at org.testng.TestRunner.run(TestRunner.java:632)
	at org.testng.SuiteRunner.runTest(SuiteRunner.java:366)
	at org.testng.SuiteRunner.runSequentially(SuiteRunner.java:361)
	at org.testng.SuiteRunner.privateRun(SuiteRunner.java:319)
	at org.testng.SuiteRunner.run(SuiteRunner.java:268)
	at org.testng.SuiteRunnerWorker.runSuite(SuiteRunnerWorker.java:52)
	at org.testng.SuiteRunnerWorker.run(SuiteRunnerWorker.java:86)
	at org.testng.TestNG.runSuitesSequentially(TestNG.java:1244)
	at org.testng.TestNG.runSuitesLocally(TestNG.java:1169)
	at org.testng.TestNG.run(TestNG.java:1064)
	at org.testng.remote.AbstractRemoteTestNG.run(AbstractRemoteTestNG.java:126)
	at org.testng.remote.RemoteTestNG.initAndRun(RemoteTestNG.java:152)
	at org.testng.remote.RemoteTestNG.main(RemoteTestNG.java:57)
]]>
            </full-stacktrace>
          </exception> <!-- java.lang.AssertionError -->
          <reporter-output>
          </reporter-output>
        </test-method> <!-- loginDDT -->
        <test-method signature="loginDDT(java.lang.String, java.lang.String)[pri:0, instance:qafactory.swaglabs.testCases.TC002_DataDriven_Login@1329eff]" started-at="2022-12-17T23:29:05Z" name="loginDDT" data-provider="LoginData" finished-at="2022-12-17T23:29:05Z" duration-ms="356" status="FAIL">
          <params>
            <param index="0">
              <value>
                <![CDATA[performance_glitch_user]]>
              </value>
            </param>
            <param index="1">
              <value>
                <![CDATA[Test3]]>
              </value>
            </param>
          </params>
          <exception class="java.lang.AssertionError">
            <message>
              <![CDATA[expected [https://www.saucedemo.com/] but found [https://www.saucedemo.com/inventory.html]]]>
            </message>
            <full-stacktrace>
              <![CDATA[java.lang.AssertionError: expected [https://www.saucedemo.com/] but found [https://www.saucedemo.com/inventory.html]
	at org.testng.Assert.fail(Assert.java:94)
	at org.testng.Assert.failNotEquals(Assert.java:513)
	at org.testng.Assert.assertEqualsImpl(Assert.java:135)
	at org.testng.Assert.assertEquals(Assert.java:116)
	at org.testng.Assert.assertEquals(Assert.java:190)
	at org.testng.Assert.assertEquals(Assert.java:200)
	at qafactory.swaglabs.testCases.TC002_DataDriven_Login.loginDDT(TC002_DataDriven_Login.java:26)
	at java.base/jdk.internal.reflect.NativeMethodAccessorImpl.invoke0(Native Method)
	at java.base/jdk.internal.reflect.NativeMethodAccessorImpl.invoke(NativeMethodAccessorImpl.java:62)
	at java.base/jdk.internal.reflect.DelegatingMethodAccessorImpl.invoke(DelegatingMethodAccessorImpl.java:43)
	at java.base/java.lang.reflect.Method.invoke(Method.java:566)
	at org.testng.internal.MethodInvocationHelper.invokeMethod(MethodInvocationHelper.java:86)
	at org.testng.internal.Invoker.invokeMethod(Invoker.java:643)
	at org.testng.internal.Invoker.invokeTestMethod(Invoker.java:820)
	at org.testng.internal.Invoker.invokeTestMethods(Invoker.java:1128)
	at org.testng.internal.TestMethodWorker.invokeTestMethods(TestMethodWorker.java:129)
	at org.testng.internal.TestMethodWorker.run(TestMethodWorker.java:112)
	at org.testng.TestRunner.privateRun(TestRunner.java:782)
	at org.testng.TestRunner.run(TestRunner.java:632)
	at org.testng.SuiteRunner.runTest(SuiteRunner.java:366)
	at org.testng.SuiteRunner.runSequentially(SuiteRunner.java:361)
	at org.testng.SuiteRunner.privateRun(SuiteRunner.java:319)
	at org.testng.SuiteRunner.run(SuiteRunner.java:268)
	at org.testng.SuiteRunnerWorker.runSuite(SuiteRunnerWorker.java:52)
	at org.testng.SuiteRunnerWorker.run(SuiteRunnerWorker.java:86)
	at org.testng.TestNG.runSuitesSequentially(TestNG.java:1244)
	at org.testng.TestNG.runSuitesLocally(TestNG.java:1169)
	at org.testng.TestNG.run(TestNG.java:1064)
	at org.testng.remote.AbstractRemoteTestNG.run(AbstractRemoteTestNG.java:126)
	at org.testng.remote.RemoteTestNG.initAndRun(RemoteTestNG.java:152)
	at org.testng.remote.RemoteTestNG.main(RemoteTestNG.java:57)
]]>
            </full-stacktrace>
          </exception> <!-- java.lang.AssertionError -->
          <reporter-output>
          </reporter-output>
        </test-method> <!-- loginDDT -->
        <test-method is-config="true" signature="tearDown()[pri:0, instance:qafactory.swaglabs.testCases.TC002_DataDriven_Login@1329eff]" started-at="2022-12-17T23:29:05Z" name="tearDown" finished-at="2022-12-17T23:29:07Z" duration-ms="1970" status="PASS">
          <reporter-output>
          </reporter-output>
        </test-method> <!-- tearDown -->
      </class> <!-- qafactory.swaglabs.testCases.TC002_DataDriven_Login -->
    </test> <!-- Default test -->
  </suite> <!-- Default suite -->
</testng-results>
