<?xml version="1.0" encoding="UTF-8"?>
<!-- Generated by org.testng.reporters.JUnitReportReporter -->
<testsuite hostname="LAPTOP-IBVEUFH3" failures="3" tests="4" name="qafactory.swaglabs.testCases.TC002_DataDriven_Login" time="4.352" errors="0" timestamp="17 Dec 2022 19:26:03 GMT">
  <testcase classname="qafactory.swaglabs.testCases.TC002_DataDriven_Login" name="loginDDT" time="0.803">
    <failure message="expected [https://www.saucedemo.com/] but found [https://www.saucedemo.com/inventory.html]" type="java.lang.AssertionError">
      <![CDATA[java.lang.AssertionError: expected [https://www.saucedemo.com/] but found [https://www.saucedemo.com/inventory.html]
	at org.testng.Assert.fail(Assert.java:94)
	at org.testng.Assert.failNotEquals(Assert.java:513)
	at org.testng.Assert.assertEqualsImpl(Assert.java:135)
	at org.testng.Assert.assertEquals(Assert.java:116)
	at org.testng.Assert.assertEquals(Assert.java:190)
	at org.testng.Assert.assertEquals(Assert.java:200)
	at qafactory.swaglabs.testCases.TC002_DataDriven_Login.loginDDT(TC002_DataDriven_Login.java:26)
	at java.base/jdk.internal.reflect.NativeMethodAccessorImpl.invoke0(Native Method)
	at java.base/jdk.internal.reflect.NativeMethodAccessorImpl.invoke(NativeMethodAccessorImpl.java:62)
	at java.base/jdk.internal.reflect.DelegatingMethodAccessorImpl.invoke(DelegatingMethodAccessorImpl.java:43)
	at java.base/java.lang.reflect.Method.invoke(Method.java:566)
	at org.testng.internal.MethodInvocationHelper.invokeMethod(MethodInvocationHelper.java:86)
	at org.testng.internal.Invoker.invokeMethod(Invoker.java:643)
	at org.testng.internal.Invoker.invokeTestMethod(Invoker.java:820)
	at org.testng.internal.Invoker.invokeTestMethods(Invoker.java:1128)
	at org.testng.internal.TestMethodWorker.invokeTestMethods(TestMethodWorker.java:129)
	at org.testng.internal.TestMethodWorker.run(TestMethodWorker.java:112)
	at org.testng.TestRunner.privateRun(TestRunner.java:782)
	at org.testng.TestRunner.run(TestRunner.java:632)
	at org.testng.SuiteRunner.runTest(SuiteRunner.java:366)
	at org.testng.SuiteRunner.runSequentially(SuiteRunner.java:361)
	at org.testng.SuiteRunner.privateRun(SuiteRunner.java:319)
	at org.testng.SuiteRunner.run(SuiteRunner.java:268)
	at org.testng.SuiteRunnerWorker.runSuite(SuiteRunnerWorker.java:52)
	at org.testng.SuiteRunnerWorker.run(SuiteRunnerWorker.java:86)
	at org.testng.TestNG.runSuitesSequentially(TestNG.java:1244)
	at org.testng.TestNG.runSuitesLocally(TestNG.java:1169)
	at org.testng.TestNG.run(TestNG.java:1064)
	at org.apache.maven.surefire.testng.TestNGExecutor.run(TestNGExecutor.java:324)
	at org.apache.maven.surefire.testng.TestNGXmlTestSuite.execute(TestNGXmlTestSuite.java:74)
	at org.apache.maven.surefire.testng.TestNGProvider.invoke(TestNGProvider.java:123)
	at org.apache.maven.surefire.booter.ForkedBooter.runSuitesInProcess(ForkedBooter.java:456)
	at org.apache.maven.surefire.booter.ForkedBooter.execute(ForkedBooter.java:169)
	at org.apache.maven.surefire.booter.ForkedBooter.run(ForkedBooter.java:595)
	at org.apache.maven.surefire.booter.ForkedBooter.main(ForkedBooter.java:581)
]]>
    </failure>
  </testcase> <!-- loginDDT -->
  <testcase classname="qafactory.swaglabs.testCases.TC002_DataDriven_Login" name="loginDDT" time="0.700">
    <failure message="expected [https://www.saucedemo.com/] but found [https://www.saucedemo.com/inventory.html]" type="java.lang.AssertionError">
      <![CDATA[java.lang.AssertionError: expected [https://www.saucedemo.com/] but found [https://www.saucedemo.com/inventory.html]
	at org.testng.Assert.fail(Assert.java:94)
	at org.testng.Assert.failNotEquals(Assert.java:513)
	at org.testng.Assert.assertEqualsImpl(Assert.java:135)
	at org.testng.Assert.assertEquals(Assert.java:116)
	at org.testng.Assert.assertEquals(Assert.java:190)
	at org.testng.Assert.assertEquals(Assert.java:200)
	at qafactory.swaglabs.testCases.TC002_DataDriven_Login.loginDDT(TC002_DataDriven_Login.java:26)
	at java.base/jdk.internal.reflect.NativeMethodAccessorImpl.invoke0(Native Method)
	at java.base/jdk.internal.reflect.NativeMethodAccessorImpl.invoke(NativeMethodAccessorImpl.java:62)
	at java.base/jdk.internal.reflect.DelegatingMethodAccessorImpl.invoke(DelegatingMethodAccessorImpl.java:43)
	at java.base/java.lang.reflect.Method.invoke(Method.java:566)
	at org.testng.internal.MethodInvocationHelper.invokeMethod(MethodInvocationHelper.java:86)
	at org.testng.internal.Invoker.invokeMethod(Invoker.java:643)
	at org.testng.internal.Invoker.invokeTestMethod(Invoker.java:820)
	at org.testng.internal.Invoker.invokeTestMethods(Invoker.java:1128)
	at org.testng.internal.TestMethodWorker.invokeTestMethods(TestMethodWorker.java:129)
	at org.testng.internal.TestMethodWorker.run(TestMethodWorker.java:112)
	at org.testng.TestRunner.privateRun(TestRunner.java:782)
	at org.testng.TestRunner.run(TestRunner.java:632)
	at org.testng.SuiteRunner.runTest(SuiteRunner.java:366)
	at org.testng.SuiteRunner.runSequentially(SuiteRunner.java:361)
	at org.testng.SuiteRunner.privateRun(SuiteRunner.java:319)
	at org.testng.SuiteRunner.run(SuiteRunner.java:268)
	at org.testng.SuiteRunnerWorker.runSuite(SuiteRunnerWorker.java:52)
	at org.testng.SuiteRunnerWorker.run(SuiteRunnerWorker.java:86)
	at org.testng.TestNG.runSuitesSequentially(TestNG.java:1244)
	at org.testng.TestNG.runSuitesLocally(TestNG.java:1169)
	at org.testng.TestNG.run(TestNG.java:1064)
	at org.apache.maven.surefire.testng.TestNGExecutor.run(TestNGExecutor.java:324)
	at org.apache.maven.surefire.testng.TestNGXmlTestSuite.execute(TestNGXmlTestSuite.java:74)
	at org.apache.maven.surefire.testng.TestNGProvider.invoke(TestNGProvider.java:123)
	at org.apache.maven.surefire.booter.ForkedBooter.runSuitesInProcess(ForkedBooter.java:456)
	at org.apache.maven.surefire.booter.ForkedBooter.execute(ForkedBooter.java:169)
	at org.apache.maven.surefire.booter.ForkedBooter.run(ForkedBooter.java:595)
	at org.apache.maven.surefire.booter.ForkedBooter.main(ForkedBooter.java:581)
]]>
    </failure>
  </testcase> <!-- loginDDT -->
  <testcase classname="qafactory.swaglabs.testCases.TC002_DataDriven_Login" name="loginDDT" time="0.889">
    <failure message="expected [https://www.saucedemo.com/] but found [https://www.saucedemo.com/inventory.html]" type="java.lang.AssertionError">
      <![CDATA[java.lang.AssertionError: expected [https://www.saucedemo.com/] but found [https://www.saucedemo.com/inventory.html]
	at org.testng.Assert.fail(Assert.java:94)
	at org.testng.Assert.failNotEquals(Assert.java:513)
	at org.testng.Assert.assertEqualsImpl(Assert.java:135)
	at org.testng.Assert.assertEquals(Assert.java:116)
	at org.testng.Assert.assertEquals(Assert.java:190)
	at org.testng.Assert.assertEquals(Assert.java:200)
	at qafactory.swaglabs.testCases.TC002_DataDriven_Login.loginDDT(TC002_DataDriven_Login.java:26)
	at java.base/jdk.internal.reflect.NativeMethodAccessorImpl.invoke0(Native Method)
	at java.base/jdk.internal.reflect.NativeMethodAccessorImpl.invoke(NativeMethodAccessorImpl.java:62)
	at java.base/jdk.internal.reflect.DelegatingMethodAccessorImpl.invoke(DelegatingMethodAccessorImpl.java:43)
	at java.base/java.lang.reflect.Method.invoke(Method.java:566)
	at org.testng.internal.MethodInvocationHelper.invokeMethod(MethodInvocationHelper.java:86)
	at org.testng.internal.Invoker.invokeMethod(Invoker.java:643)
	at org.testng.internal.Invoker.invokeTestMethod(Invoker.java:820)
	at org.testng.internal.Invoker.invokeTestMethods(Invoker.java:1128)
	at org.testng.internal.TestMethodWorker.invokeTestMethods(TestMethodWorker.java:129)
	at org.testng.internal.TestMethodWorker.run(TestMethodWorker.java:112)
	at org.testng.TestRunner.privateRun(TestRunner.java:782)
	at org.testng.TestRunner.run(TestRunner.java:632)
	at org.testng.SuiteRunner.runTest(SuiteRunner.java:366)
	at org.testng.SuiteRunner.runSequentially(SuiteRunner.java:361)
	at org.testng.SuiteRunner.privateRun(SuiteRunner.java:319)
	at org.testng.SuiteRunner.run(SuiteRunner.java:268)
	at org.testng.SuiteRunnerWorker.runSuite(SuiteRunnerWorker.java:52)
	at org.testng.SuiteRunnerWorker.run(SuiteRunnerWorker.java:86)
	at org.testng.TestNG.runSuitesSequentially(TestNG.java:1244)
	at org.testng.TestNG.runSuitesLocally(TestNG.java:1169)
	at org.testng.TestNG.run(TestNG.java:1064)
	at org.apache.maven.surefire.testng.TestNGExecutor.run(TestNGExecutor.java:324)
	at org.apache.maven.surefire.testng.TestNGXmlTestSuite.execute(TestNGXmlTestSuite.java:74)
	at org.apache.maven.surefire.testng.TestNGProvider.invoke(TestNGProvider.java:123)
	at org.apache.maven.surefire.booter.ForkedBooter.runSuitesInProcess(ForkedBooter.java:456)
	at org.apache.maven.surefire.booter.ForkedBooter.execute(ForkedBooter.java:169)
	at org.apache.maven.surefire.booter.ForkedBooter.run(ForkedBooter.java:595)
	at org.apache.maven.surefire.booter.ForkedBooter.main(ForkedBooter.java:581)
]]>
    </failure>
  </testcase> <!-- loginDDT -->
  <testcase classname="qafactory.swaglabs.testCases.TC002_DataDriven_Login" name="loginDDT" time="1.960"/>
</testsuite> <!-- qafactory.swaglabs.testCases.TC002_DataDriven_Login -->
